Workbook

Sheet Final Marks
A1: Module Code :EN1060 | D1: Module : Signals and Systems
A2: Credit: | B2: GPA 3.0
D3: [Only light yellow areas may be filled]
A4: Summary
A5: Grade | B5: Normal Range | D5: Minimum Actual | E5: No. | F5: % | H5: Examiner's Comments
A6: A+ | B6: 85 and Above | D6: 85 | E6: =K22 -> 10 | F6: =IF(E$19>0,E6/E$19,0) -> 0.099009901
A7: A | B7: 75 to 84 | D7: 75 | E7: =L22 -> 43 | F7: =IF(E$19>0,E7/E$19,0) -> 0.42574257
A8: A- | B8: 70 to 74 | D8: 70 | E8: =M22 -> 23 | F8: =IF(E$19>0,E8/E$19,0) -> 0.22772277
A9: B+ | B9: 65 to 69 | D9: 65 | E9: =N22 -> 11 | F9: =IF(E$19>0,E9/E$19,0) -> 0.10891089
A10: B | B10: 60 to 64 | D10: 60 | E10: =O22 -> 6 | F10: =IF(E$19>0,E10/E$19,0) -> 0.059405941 | H10: ………………………….
A11: B- | B11: 55 to 59 | D11: 55 | E11: =P22 -> 4 | F11: =IF(E$19>0,E11/E$19,0) -> 0.03960396 | H11: Signature and Date
A12: C+ | B12: 50 to 54 | D12: 50 | E12: =Q22 -> 3 | F12: =IF(E$19>0,E12/E$19,0) -> 0.02970297
A13: C | B13: 45 to 49 | D13: 45 | E13: =R22 -> 0 | F13: =IF(E$19>0,E13/E$19,0) -> 0 | H13: Moderator's Comments
A14: C- | B14: 40 to 44 | D14: 40 | E14: =S22 -> 1 | F14: =IF(E$19>0,E14/E$19,0) -> 0.0099009901
A15: D | B15: 35 to 39 | D15: 35 | E15: =T22 -> 0 | F15: =IF(E$19>0,E15/E$19,0) -> 0
A16: I | B16: 34 and Below for either WE or CA | E16: =U22 -> 0 | F16: =IF(E$19>0,E16/E$19,0) -> 0
A17: F | B17: Below 34 for both WE and CA | E17: =V22 -> 0 | F17: =IF(E$19>0,E17/E$19,0) -> 0 | U17: =IF(AND(Y25<$R$25,Y25>=$S$25),"C-",IF(AND(Y25<$S$23,Y25>=$T$25),"D",IF(Y25<$T$25,"I","***"))) -> ***
A18: N | E18: =W22 -> 0 | F18: =IF(E$19>0,E18/E$19,0) -> 0 | H18: ………………………….
A19: Total | B19: Total | E19: =SUM(E6:E18) -> 101 | H19: Signature and Date
C20: Continuous Assessment >=75% | E20: =SUM(J25:J34) -> 10 | F20: =IF(E$19>0,E20/E$19,0) -> 0.099009901
K22: =SUM(K25:K125) -> 10 | L22: =SUM(L25:L125) -> 43 | M22: =SUM(M25:M125) -> 23 | N22: =SUM(N25:N125) -> 11 | O22: =SUM(O25:O125) -> 6 | P22: =SUM(P25:P125) -> 4 | Q22: =SUM(Q25:Q125) -> 3 | R22: =SUM(R25:R125) -> 0 | ... W22: =SUM(W25:W125) -> 0
A23: Status* | B23: Index No | C23: Name | D23: Moderated | E23: Calculated | F23: Final Marks | G23: Exam | H23: Continuous Assesment | I23: Continuous Assesment | K23: =D6-0.5 -> 84.5 | L23: =D7-0.5 -> 74.5 | M23: =D8-0.5 -> 69.5 | N23: =D9-0.5 -> 64.5 | O23: =D10-0.5 -> 59.5 | P23: =D11-0.5 -> 54.5 | Q23: =D12-0.5 -> 49.5 | R23: =D13-0.5 -> 44.5 | S23: =D14-0.5 -> 39.5 | T23: =D15-0.5 -> 34.5 | Y23: Final
D24: Grade | E24: Grade | F24: 1 | G24: 0.4 | H24: 0.6 | I24: 0.6 | J24: >=75% | K24: A+ | L24: A | M24: A- | N24: B+ | O24: B | P24: B- | Q24: C+ | R24: C | S24: C- | T24: D | U24: I | V24: F | W24: N | Y24: 1 | AA24: Repeat Grade | AC24: Grade
B25: ='Detailed Marks'!A4 -> 200370K | C25: ='Detailed Marks'!B4 -> MADUWANTHA L.H.H. | E25: =+IF(AND(C25="",B25=""),"",IF(AA25=0,AC25,AA25)) -> A | F25: =G25+H25 -> 75.02 | G25: ='Detailed Marks'!L4/'Detailed Marks'!$L$3*'Final Marks'!$G$24 -> 26.6 | H25: =I25*H$24/I$24 -> 48.42 | I25: ='Detailed Marks'!M4 -> 48.42 | J25: =IF(I25/$I$24>=75,1,"") -> 1 | K25: =IF($D25="",IF($E25=K$24,1,0),IF($D25=K$24,1,0)) -> 0 | L25: =IF($D25="",IF($E25=L$24,1,0),IF($D25=L$24,1,0)) -> 1 | M25: =IF($D25="",IF($E25=M$24,1,0),IF($D25=M$24,1,0)) -> 0 | N25: =IF($D25="",IF($E25=N$24,1,0),IF($D25=N$24,1,0)) -> 0 | O25: =IF($D25="",IF($E25=O$24,1,0),IF($D25=O$24,1,0)) -> 0 | P25: =IF($D25="",IF($E25=P$24,1,0),IF($D25=P$24,1,0)) -> 0 | Q25: =IF($D25="",IF($E25=Q$24,1,0),IF($D25=Q$24,1,0)) -> 0 | R25: =IF($D25="",IF($E25=R$24,1,0),IF($D25=R$24,1,0)) -> 0 | ... T25: =IF($D25="",IF($E25=T$24,1,0),IF($D25=T$24,1,0)) -> 0 | U25: =IF($D25="",IF(LEFT($E25,1)=U$24,1,0),IF(LEFT($D25,1)=U$24,1,0)) -> 0 | V25: =IF($D25="",IF($E25=V$24,1,0),IF($D25=V$24,1,0)) -> 0 | W25: =IF($D25="",IF($E25=W$24,1,0),IF($D25=W$24,1,0)) -> 0 | Y25: =F25 -> 75.02 | AA25: =+IF(OR(A25="",A25="N"),0, IF(A25="U", IF(OR(AC25="I-we",AC25="I-ca",AC25="F"),"**I", IF(Y25>=R$23,"C", IF(Y25>=S$23,"C-","**D"))), IF(A25="PF", IF(OR(AC25="I-we",AC25="I-ca",AC25="F"),AC25, IF(Y25>=R$23,"C", IF(Y25>=S$23,"C-","**D"))), IF(A25="PI-ca",IF(AC25="I-we","DATA",IF(AC25="I-ca",AC25, IF(Y25>=R$23,"C", IF(Y25>=S$23,"C-",IF(Y25>=T$23,"D","DATA"))))),IF(A25="PI-we", IF(AC25="I-ca","DATA",IF(AC25="I-we",AC25,IF(Y25>=R$23,"C", IF(Y25>=S$23,"C-",IF(Y25>=T$23,"D","DATA")))) ))) ))) -> 0 | AC25: =IF(AND(H25>=$D$15*$H$24,G25>=$D$15*$G$24),IF(F25>=$O$23,IF(F25>=$K$23,"A+",IF(F25>=$L$23,"A",IF(F25>=$M$23,"A-",IF(F25>=$N$23,"B+","B")))),IF(F25<$T$23,"I",IF(F25<$S$23,"D",IF(F25<$R$23,"C-",IF(F25<$Q$23,"C",IF(F25<$P$23,"C+",IF(F25<$O$23,"B-","B"))))))),IF(AND(H25<$D$15*$H$24,G25<$D$15*$G$24),"F",IF(H25<$D$15*$H$24,"I-ca","I-we"))) -> A
B26: ='Detailed Marks'!A5 -> 210003B | C26: ='Detailed Marks'!B5 -> ABEWICKREMA A.S.J. | E26: =+IF(AND(C26="",B26=""),"",IF(AA26=0,AC26,AA26)) -> A | F26: =G26+H26 -> 74.57 | G26: ='Detailed Marks'!L5/'Detailed Marks'!$L$3*'Final Marks'!$G$24 -> 23.4 | H26: =I26*H$24/I$24 -> 51.17 | I26: ='Detailed Marks'!M5 -> 51.17 | J26: =IF(I26/$I$24>=75,1,"") -> 1 | K26: =IF($D26="",IF($E26=K$24,1,0),IF($D26=K$24,1,0)) -> 0 | L26: =IF($D26="",IF($E26=L$24,1,0),IF($D26=L$24,1,0)) -> 1 | M26: =IF($D26="",IF($E26=M$24,1,0),IF($D26=M$24,1,0)) -> 0 | N26: =IF($D26="",IF($E26=N$24,1,0),IF($D26=N$24,1,0)) -> 0 | O26: =IF($D26="",IF($E26=O$24,1,0),IF($D26=O$24,1,0)) -> 0 | P26: =IF($D26="",IF($E26=P$24,1,0),IF($D26=P$24,1,0)) -> 0 | Q26: =IF($D26="",IF($E26=Q$24,1,0),IF($D26=Q$24,1,0)) -> 0 | R26: =IF($D26="",IF($E26=R$24,1,0),IF($D26=R$24,1,0)) -> 0 | ... T26: =IF($D26="",IF($E26=T$24,1,0),IF($D26=T$24,1,0)) -> 0 | U26: =IF($D26="",IF(LEFT($E26,1)=U$24,1,0),IF(LEFT($D26,1)=U$24,1,0)) -> 0 | V26: =IF($D26="",IF($E26=V$24,1,0),IF($D26=V$24,1,0)) -> 0 | W26: =IF($D26="",IF($E26=W$24,1,0),IF($D26=W$24,1,0)) -> 0 | Y26: =F26 -> 74.57 | AA26: =+IF(OR(A26="",A26="N"),0, IF(A26="U", IF(OR(AC26="I-we",AC26="I-ca",AC26="F"),"**I", IF(Y26>=R$23,"C", IF(Y26>=S$23,"C-","**D"))), IF(A26="PF", IF(OR(AC26="I-we",AC26="I-ca",AC26="F"),AC26, IF(Y26>=R$23,"C", IF(Y26>=S$23,"C-","**D"))), IF(A26="PI-ca",IF(AC26="I-we","DATA",IF(AC26="I-ca",AC26, IF(Y26>=R$23,"C", IF(Y26>=S$23,"C-",IF(Y26>=T$23,"D","DATA"))))),IF(A26="PI-we", IF(AC26="I-ca","DATA",IF(AC26="I-we",AC26,IF(Y26>=R$23,"C", IF(Y26>=S$23,"C-",IF(Y26>=T$23,"D","DATA")))) ))) ))) -> 0 | AC26: =IF(AND(H26>=$D$15*$H$24,G26>=$D$15*$G$24),IF(F26>=$O$23,IF(F26>=$K$23,"A+",IF(F26>=$L$23,"A",IF(F26>=$M$23,"A-",IF(F26>=$N$23,"B+","B")))),IF(F26<$T$23,"I",IF(F26<$S$23,"D",IF(F26<$R$23,"C-",IF(F26<$Q$23,"C",IF(F26<$P$23,"C+",IF(F26<$O$23,"B-","B"))))))),IF(AND(H26<$D$15*$H$24,G26<$D$15*$G$24),"F",IF(H26<$D$15*$H$24,"I-ca","I-we"))) -> A
B27: ='Detailed Marks'!A6 -> 210005H | C27: ='Detailed Marks'!B6 -> ABEYRATHNA S.M.S.M.B. | E27: =+IF(AND(C27="",B27=""),"",IF(AA27=0,AC27,AA27)) -> A- | F27: =G27+H27 -> 71.65 | G27: ='Detailed Marks'!L6/'Detailed Marks'!$L$3*'Final Marks'!$G$24 -> 20.4 | H27: =I27*H$24/I$24 -> 51.25 | I27: ='Detailed Marks'!M6 -> 51.25 | J27: =IF(I27/$I$24>=75,1,"") -> 1 | K27: =IF($D27="",IF($E27=K$24,1,0),IF($D27=K$24,1,0)) -> 0 | L27: =IF($D27="",IF($E27=L$24,1,0),IF($D27=L$24,1,0)) -> 0 | M27: =IF($D27="",IF($E27=M$24,1,0),IF($D27=M$24,1,0)) -> 1 | N27: =IF($D27="",IF($E27=N$24,1,0),IF($D27=N$24,1,0)) -> 0 | O27: =IF($D27="",IF($E27=O$24,1,0),IF($D27=O$24,1,0)) -> 0 | P27: =IF($D27="",IF($E27=P$24,1,0),IF($D27=P$24,1,0)) -> 0 | Q27: =IF($D27="",IF($E27=Q$24,1,0),IF($D27=Q$24,1,0)) -> 0 | R27: =IF($D27="",IF($E27=R$24,1,0),IF($D27=R$24,1,0)) -> 0 | ... T27: =IF($D27="",IF($E27=T$24,1,0),IF($D27=T$24,1,0)) -> 0 | U27: =IF($D27="",IF(LEFT($E27,1)=U$24,1,0),IF(LEFT($D27,1)=U$24,1,0)) -> 0 | V27: =IF($D27="",IF($E27=V$24,1,0),IF($D27=V$24,1,0)) -> 0 | W27: =IF($D27="",IF($E27=W$24,1,0),IF($D27=W$24,1,0)) -> 0 | Y27: =F27 -> 71.65 | AA27: =+IF(OR(A27="",A27="N"),0, IF(A27="U", IF(OR(AC27="I-we",AC27="I-ca",AC27="F"),"**I", IF(Y27>=R$23,"C", IF(Y27>=S$23,"C-","**D"))), IF(A27="PF", IF(OR(AC27="I-we",AC27="I-ca",AC27="F"),AC27, IF(Y27>=R$23,"C", IF(Y27>=S$23,"C-","**D"))), IF(A27="PI-ca",IF(AC27="I-we","DATA",IF(AC27="I-ca",AC27, IF(Y27>=R$23,"C", IF(Y27>=S$23,"C-",IF(Y27>=T$23,"D","DATA"))))),IF(A27="PI-we", IF(AC27="I-ca","DATA",IF(AC27="I-we",AC27,IF(Y27>=R$23,"C", IF(Y27>=S$23,"C-",IF(Y27>=T$23,"D","DATA")))) ))) ))) -> 0 | AC27: =IF(AND(H27>=$D$15*$H$24,G27>=$D$15*$G$24),IF(F27>=$O$23,IF(F27>=$K$23,"A+",IF(F27>=$L$23,"A",IF(F27>=$M$23,"A-",IF(F27>=$N$23,"B+","B")))),IF(F27<$T$23,"I",IF(F27<$S$23,"D",IF(F27<$R$23,"C-",IF(F27<$Q$23,"C",IF(F27<$P$23,"C+",IF(F27<$O$23,"B-","B"))))))),IF(AND(H27<$D$15*$H$24,G27<$D$15*$G$24),"F",IF(H27<$D$15*$H$24,"I-ca","I-we"))) -> A-
B28: ='Detailed Marks'!A7 -> 210014J | C28: ='Detailed Marks'!B7 -> ABEYWARDANA K.D.W. | E28: =+IF(AND(C28="",B28=""),"",IF(AA28=0,AC28,AA28)) -> A | F28: =G28+H28 -> 74.68 | G28: ='Detailed Marks'!L7/'Detailed Marks'!$L$3*'Final Marks'!$G$24 -> 22.6 | H28: =I28*H$24/I$24 -> 52.08 | I28: ='Detailed Marks'!M7 -> 52.08 | J28: =IF(I28/$I$24>=75,1,"") -> 1 | K28: =IF($D28="",IF($E28=K$24,1,0),IF($D28=K$24,1,0)) -> 0 | L28: =IF($D28="",IF($E28=L$24,1,0),IF($D28=L$24,1,0)) -> 1 | M28: =IF($D28="",IF($E28=M$24,1,0),IF($D28=M$24,1,0)) -> 0 | N28: =IF($D28="",IF($E28=N$24,1,0),IF($D28=N$24,1,0)) -> 0 | O28: =IF($D28="",IF($E28=O$24,1,0),IF($D28=O$24,1,0)) -> 0 | P28: =IF($D28="",IF($E28=P$24,1,0),IF($D28=P$24,1,0)) -> 0 | Q28: =IF($D28="",IF($E28=Q$24,1,0),IF($D28=Q$24,1,0)) -> 0 | R28: =IF($D28="",IF($E28=R$24,1,0),IF($D28=R$24,1,0)) -> 0 | ... T28: =IF($D28="",IF($E28=T$24,1,0),IF($D28=T$24,1,0)) -> 0 | U28: =IF($D28="",IF(LEFT($E28,1)=U$24,1,0),IF(LEFT($D28,1)=U$24,1,0)) -> 0 | V28: =IF($D28="",IF($E28=V$24,1,0),IF($D28=V$24,1,0)) -> 0 | W28: =IF($D28="",IF($E28=W$24,1,0),IF($D28=W$24,1,0)) -> 0 | Y28: =F28 -> 74.68 | AA28: =+IF(OR(A28="",A28="N"),0, IF(A28="U", IF(OR(AC28="I-we",AC28="I-ca",AC28="F"),"**I", IF(Y28>=R$23,"C", IF(Y28>=S$23,"C-","**D"))), IF(A28="PF", IF(OR(AC28="I-we",AC28="I-ca",AC28="F"),AC28, IF(Y28>=R$23,"C", IF(Y28>=S$23,"C-","**D"))), IF(A28="PI-ca",IF(AC28="I-we","DATA",IF(AC28="I-ca",AC28, IF(Y28>=R$23,"C", IF(Y28>=S$23,"C-",IF(Y28>=T$23,"D","DATA"))))),IF(A28="PI-we", IF(AC28="I-ca","DATA",IF(AC28="I-we",AC28,IF(Y28>=R$23,"C", IF(Y28>=S$23,"C-",IF(Y28>=T$23,"D","DATA")))) ))) ))) -> 0 | AC28: =IF(AND(H28>=$D$15*$H$24,G28>=$D$15*$G$24),IF(F28>=$O$23,IF(F28>=$K$23,"A+",IF(F28>=$L$23,"A",IF(F28>=$M$23,"A-",IF(F28>=$N$23,"B+","B")))),IF(F28<$T$23,"I",IF(F28<$S$23,"D",IF(F28<$R$23,"C-",IF(F28<$Q$23,"C",IF(F28<$P$23,"C+",IF(F28<$O$23,"B-","B"))))))),IF(AND(H28<$D$15*$H$24,G28<$D$15*$G$24),"F",IF(H28<$D$15*$H$24,"I-ca","I-we"))) -> A
B29: ='Detailed Marks'!A8 -> 210019E | C29: ='Detailed Marks'!B8 -> ABITHAN A. | E29: =+IF(AND(C29="",B29=""),"",IF(AA29=0,AC29,AA29)) -> B+ | F29: =G29+H29 -> 66.13 | G29: ='Detailed Marks'!L8/'Detailed Marks'!$L$3*'Final Marks'!$G$24 -> 16.8 | H29: =I29*H$24/I$24 -> 49.33 | I29: ='Detailed Marks'!M8 -> 49.33 | J29: =IF(I29/$I$24>=75,1,"") -> 1 | K29: =IF($D29="",IF($E29=K$24,1,0),IF($D29=K$24,1,0)) -> 0 | L29: =IF($D29="",IF($E29=L$24,1,0),IF($D29=L$24,1,0)) -> 0 | M29: =IF($D29="",IF($E29=M$24,1,0),IF($D29=M$24,1,0)) -> 0 | N29: =IF($D29="",IF($E29=N$24,1,0),IF($D29=N$24,1,0)) -> 1 | O29: =IF($D29="",IF($E29=O$24,1,0),IF($D29=O$24,1,0)) -> 0 | P29: =IF($D29="",IF($E29=P$24,1,0),IF($D29=P$24,1,0)) -> 0 | Q29: =IF($D29="",IF($E29=Q$24,1,0),IF($D29=Q$24,1,0)) -> 0 | R29: =IF($D29="",IF($E29=R$24,1,0),IF($D29=R$24,1,0)) -> 0 | ... T29: =IF($D29="",IF($E29=T$24,1,0),IF($D29=T$24,1,0)) -> 0 | U29: =IF($D29="",IF(LEFT($E29,1)=U$24,1,0),IF(LEFT($D29,1)=U$24,1,0)) -> 0 | V29: =IF($D29="",IF($E29=V$24,1,0),IF($D29=V$24,1,0)) -> 0 | W29: =IF($D29="",IF($E29=W$24,1,0),IF($D29=W$24,1,0)) -> 0 | Y29: =F29 -> 66.13 | AA29: =+IF(OR(A29="",A29="N"),0, IF(A29="U", IF(OR(AC29="I-we",AC29="I-ca",AC29="F"),"**I", IF(Y29>=R$23,"C", IF(Y29>=S$23,"C-","**D"))), IF(A29="PF", IF(OR(AC29="I-we",AC29="I-ca",AC29="F"),AC29, IF(Y29>=R$23,"C", IF(Y29>=S$23,"C-","**D"))), IF(A29="PI-ca",IF(AC29="I-we","DATA",IF(AC29="I-ca",AC29, IF(Y29>=R$23,"C", IF(Y29>=S$23,"C-",IF(Y29>=T$23,"D","DATA"))))),IF(A29="PI-we", IF(AC29="I-ca","DATA",IF(AC29="I-we",AC29,IF(Y29>=R$23,"C", IF(Y29>=S$23,"C-",IF(Y29>=T$23,"D","DATA")))) ))) ))) -> 0 | AC29: =IF(AND(H29>=$D$15*$H$24,G29>=$D$15*$G$24),IF(F29>=$O$23,IF(F29>=$K$23,"A+",IF(F29>=$L$23,"A",IF(F29>=$M$23,"A-",IF(F29>=$N$23,"B+","B")))),IF(F29<$T$23,"I",IF(F29<$S$23,"D",IF(F29<$R$23,"C-",IF(F29<$Q$23,"C",IF(F29<$P$23,"C+",IF(F29<$O$23,"B-","B"))))))),IF(AND(H29<$D$15*$H$24,G29<$D$15*$G$24),"F",IF(H29<$D$15*$H$24,"I-ca","I-we"))) -> B+
B30: ='Detailed Marks'!A9 -> 210021D | C30: ='Detailed Marks'!B9 -> ADIKARAM W.K.D.N.E. | E30: =+IF(AND(C30="",B30=""),"",IF(AA30=0,AC30,AA30)) -> B+ | F30: =G30+H30 -> 66.28 | G30: ='Detailed Marks'!L9/'Detailed Marks'!$L$3*'Final Marks'!$G$24 -> 17.4 | H30: =I30*H$24/I$24 -> 48.88 | I30: ='Detailed Marks'!M9 -> 48.88 | J30: =IF(I30/$I$24>=75,1,"") -> 1 | K30: =IF($D30="",IF($E30=K$24,1,0),IF($D30=K$24,1,0)) -> 0 | L30: =IF($D30="",IF($E30=L$24,1,0),IF($D30=L$24,1,0)) -> 0 | M30: =IF($D30="",IF($E30=M$24,1,0),IF($D30=M$24,1,0)) -> 0 | N30: =IF($D30="",IF($E30=N$24,1,0),IF($D30=N$24,1,0)) -> 1 | O30: =IF($D30="",IF($E30=O$24,1,0),IF($D30=O$24,1,0)) -> 0 | P30: =IF($D30="",IF($E30=P$24,1,0),IF($D30=P$24,1,0)) -> 0 | Q30: =IF($D30="",IF($E30=Q$24,1,0),IF($D30=Q$24,1,0)) -> 0 | R30: =IF($D30="",IF($E30=R$24,1,0),IF($D30=R$24,1,0)) -> 0 | ... T30: =IF($D30="",IF($E30=T$24,1,0),IF($D30=T$24,1,0)) -> 0 | U30: =IF($D30="",IF(LEFT($E30,1)=U$24,1,0),IF(LEFT($D30,1)=U$24,1,0)) -> 0 | V30: =IF($D30="",IF($E30=V$24,1,0),IF($D30=V$24,1,0)) -> 0 | W30: =IF($D30="",IF($E30=W$24,1,0),IF($D30=W$24,1,0)) -> 0 | Y30: =F30 -> 66.28 | AA30: =+IF(OR(A30="",A30="N"),0, IF(A30="U", IF(OR(AC30="I-we",AC30="I-ca",AC30="F"),"**I", IF(Y30>=R$23,"C", IF(Y30>=S$23,"C-","**D"))), IF(A30="PF", IF(OR(AC30="I-we",AC30="I-ca",AC30="F"),AC30, IF(Y30>=R$23,"C", IF(Y30>=S$23,"C-","**D"))), IF(A30="PI-ca",IF(AC30="I-we","DATA",IF(AC30="I-ca",AC30, IF(Y30>=R$23,"C", IF(Y30>=S$23,"C-",IF(Y30>=T$23,"D","DATA"))))),IF(A30="PI-we", IF(AC30="I-ca","DATA",IF(AC30="I-we",AC30,IF(Y30>=R$23,"C", IF(Y30>=S$23,"C-",IF(Y30>=T$23,"D","DATA")))) ))) ))) -> 0 | AC30: =IF(AND(H30>=$D$15*$H$24,G30>=$D$15*$G$24),IF(F30>=$O$23,IF(F30>=$K$23,"A+",IF(F30>=$L$23,"A",IF(F30>=$M$23,"A-",IF(F30>=$N$23,"B+","B")))),IF(F30<$T$23,"I",IF(F30<$S$23,"D",IF(F30<$R$23,"C-",IF(F30<$Q$23,"C",IF(F30<$P$23,"C+",IF(F30<$O$23,"B-","B"))))))),IF(AND(H30<$D$15*$H$24,G30<$D$15*$G$24),"F",IF(H30<$D$15*$H$24,"I-ca","I-we"))) -> B+
B31: ='Detailed Marks'!A10 -> 210022G | C31: ='Detailed Marks'!B10 -> ADIKARI A.A.S.D. | E31: =+IF(AND(C31="",B31=""),"",IF(AA31=0,AC31,AA31)) -> A | F31: =G31+H31 -> 82.37 | G31: ='Detailed Marks'!L10/'Detailed Marks'!$L$3*'Final Marks'!$G$24 -> 29.2 | H31: =I31*H$24/I$24 -> 53.17 | I31: ='Detailed Marks'!M10 -> 53.17 | J31: =IF(I31/$I$24>=75,1,"") -> 1 | K31: =IF($D31="",IF($E31=K$24,1,0),IF($D31=K$24,1,0)) -> 0 | L31: =IF($D31="",IF($E31=L$24,1,0),IF($D31=L$24,1,0)) -> 1 | M31: =IF($D31="",IF($E31=M$24,1,0),IF($D31=M$24,1,0)) -> 0 | N31: =IF($D31="",IF($E31=N$24,1,0),IF($D31=N$24,1,0)) -> 0 | O31: =IF($D31="",IF($E31=O$24,1,0),IF($D31=O$24,1,0)) -> 0 | P31: =IF($D31="",IF($E31=P$24,1,0),IF($D31=P$24,1,0)) -> 0 | Q31: =IF($D31="",IF($E31=Q$24,1,0),IF($D31=Q$24,1,0)) -> 0 | R31: =IF($D31="",IF($E31=R$24,1,0),IF($D31=R$24,1,0)) -> 0 | ... T31: =IF($D31="",IF($E31=T$24,1,0),IF($D31=T$24,1,0)) -> 0 | U31: =IF($D31="",IF(LEFT($E31,1)=U$24,1,0),IF(LEFT($D31,1)=U$24,1,0)) -> 0 | V31: =IF($D31="",IF($E31=V$24,1,0),IF($D31=V$24,1,0)) -> 0 | W31: =IF($D31="",IF($E31=W$24,1,0),IF($D31=W$24,1,0)) -> 0 | Y31: =F31 -> 82.37 | AA31: =+IF(OR(A31="",A31="N"),0, IF(A31="U", IF(OR(AC31="I-we",AC31="I-ca",AC31="F"),"**I", IF(Y31>=R$23,"C", IF(Y31>=S$23,"C-","**D"))), IF(A31="PF", IF(OR(AC31="I-we",AC31="I-ca",AC31="F"),AC31, IF(Y31>=R$23,"C", IF(Y31>=S$23,"C-","**D"))), IF(A31="PI-ca",IF(AC31="I-we","DATA",IF(AC31="I-ca",AC31, IF(Y31>=R$23,"C", IF(Y31>=S$23,"C-",IF(Y31>=T$23,"D","DATA"))))),IF(A31="PI-we", IF(AC31="I-ca","DATA",IF(AC31="I-we",AC31,IF(Y31>=R$23,"C", IF(Y31>=S$23,"C-",IF(Y31>=T$23,"D","DATA")))) ))) ))) -> 0 | AC31: =IF(AND(H31>=$D$15*$H$24,G31>=$D$15*$G$24),IF(F31>=$O$23,IF(F31>=$K$23,"A+",IF(F31>=$L$23,"A",IF(F31>=$M$23,"A-",IF(F31>=$N$23,"B+","B")))),IF(F31<$T$23,"I",IF(F31<$S$23,"D",IF(F31<$R$23,"C-",IF(F31<$Q$23,"C",IF(F31<$P$23,"C+",IF(F31<$O$23,"B-","B"))))))),IF(AND(H31<$D$15*$H$24,G31<$D$15*$G$24),"F",IF(H31<$D$15*$H$24,"I-ca","I-we"))) -> A
B32: ='Detailed Marks'!A11 -> 210027C | C32: ='Detailed Marks'!B11 -> ALAHAKOON U.M.Y.B. | E32: =+IF(AND(C32="",B32=""),"",IF(AA32=0,AC32,AA32)) -> A | F32: =G32+H32 -> 75.17 | G32: ='Detailed Marks'!L11/'Detailed Marks'!$L$3*'Final Marks'!$G$24 -> 26.4 | H32: =I32*H$24/I$24 -> 48.77 | I32: ='Detailed Marks'!M11 -> 48.77 | J32: =IF(I32/$I$24>=75,1,"") -> 1 | K32: =IF($D32="",IF($E32=K$24,1,0),IF($D32=K$24,1,0)) -> 0 | L32: =IF($D32="",IF($E32=L$24,1,0),IF($D32=L$24,1,0)) -> 1 | M32: =IF($D32="",IF($E32=M$24,1,0),IF($D32=M$24,1,0)) -> 0 | N32: =IF($D32="",IF($E32=N$24,1,0),IF($D32=N$24,1,0)) -> 0 | O32: =IF($D32="",IF($E32=O$24,1,0),IF($D32=O$24,1,0)) -> 0 | P32: =IF($D32="",IF($E32=P$24,1,0),IF($D32=P$24,1,0)) -> 0 | Q32: =IF($D32="",IF($E32=Q$24,1,0),IF($D32=Q$24,1,0)) -> 0 | R32: =IF($D32="",IF($E32=R$24,1,0),IF($D32=R$24,1,0)) -> 0 | ... T32: =IF($D32="",IF($E32=T$24,1,0),IF($D32=T$24,1,0)) -> 0 | U32: =IF($D32="",IF(LEFT($E32,1)=U$24,1,0),IF(LEFT($D32,1)=U$24,1,0)) -> 0 | V32: =IF($D32="",IF($E32=V$24,1,0),IF($D32=V$24,1,0)) -> 0 | W32: =IF($D32="",IF($E32=W$24,1,0),IF($D32=W$24,1,0)) -> 0 | Y32: =F32 -> 75.17 | AA32: =+IF(OR(A32="",A32="N"),0, IF(A32="U", IF(OR(AC32="I-we",AC32="I-ca",AC32="F"),"**I", IF(Y32>=R$23,"C", IF(Y32>=S$23,"C-","**D"))), IF(A32="PF", IF(OR(AC32="I-we",AC32="I-ca",AC32="F"),AC32, IF(Y32>=R$23,"C", IF(Y32>=S$23,"C-","**D"))), IF(A32="PI-ca",IF(AC32="I-we","DATA",IF(AC32="I-ca",AC32, IF(Y32>=R$23,"C", IF(Y32>=S$23,"C-",IF(Y32>=T$23,"D","DATA"))))),IF(A32="PI-we", IF(AC32="I-ca","DATA",IF(AC32="I-we",AC32,IF(Y32>=R$23,"C", IF(Y32>=S$23,"C-",IF(Y32>=T$23,"D","DATA")))) ))) ))) -> 0 | AC32: =IF(AND(H32>=$D$15*$H$24,G32>=$D$15*$G$24),IF(F32>=$O$23,IF(F32>=$K$23,"A+",IF(F32>=$L$23,"A",IF(F32>=$M$23,"A-",IF(F32>=$N$23,"B+","B")))),IF(F32<$T$23,"I",IF(F32<$S$23,"D",IF(F32<$R$23,"C-",IF(F32<$Q$23,"C",IF(F32<$P$23,"C+",IF(F32<$O$23,"B-","B"))))))),IF(AND(H32<$D$15*$H$24,G32<$D$15*$G$24),"F",IF(H32<$D$15*$H$24,"I-ca","I-we"))) -> A
B33: ='Detailed Marks'!A12 -> 210031H | C33: ='Detailed Marks'!B12 -> AMARASINGHE A.A.W.L.R. | E33: =+IF(AND(C33="",B33=""),"",IF(AA33=0,AC33,AA33)) -> A | F33: =G33+H33 -> 80.25 | G33: ='Detailed Marks'!L12/'Detailed Marks'!$L$3*'Final Marks'!$G$24 -> 25 | H33: =I33*H$24/I$24 -> 55.25 | I33: ='Detailed Marks'!M12 -> 55.25 | J33: =IF(I33/$I$24>=75,1,"") -> 1 | K33: =IF($D33="",IF($E33=K$24,1,0),IF($D33=K$24,1,0)) -> 0 | L33: =IF($D33="",IF($E33=L$24,1,0),IF($D33=L$24,1,0)) -> 1 | M33: =IF($D33="",IF($E33=M$24,1,0),IF($D33=M$24,1,0)) -> 0 | N33: =IF($D33="",IF($E33=N$24,1,0),IF($D33=N$24,1,0)) -> 0 | O33: =IF($D33="",IF($E33=O$24,1,0),IF($D33=O$24,1,0)) -> 0 | P33: =IF($D33="",IF($E33=P$24,1,0),IF($D33=P$24,1,0)) -> 0 | Q33: =IF($D33="",IF($E33=Q$24,1,0),IF($D33=Q$24,1,0)) -> 0 | R33: =IF($D33="",IF($E33=R$24,1,0),IF($D33=R$24,1,0)) -> 0 | ... T33: =IF($D33="",IF($E33=T$24,1,0),IF($D33=T$24,1,0)) -> 0 | U33: =IF($D33="",IF(LEFT($E33,1)=U$24,1,0),IF(LEFT($D33,1)=U$24,1,0)) -> 0 | V33: =IF($D33="",IF($E33=V$24,1,0),IF($D33=V$24,1,0)) -> 0 | W33: =IF($D33="",IF($E33=W$24,1,0),IF($D33=W$24,1,0)) -> 0 | Y33: =F33 -> 80.25 | AA33: =+IF(OR(A33="",A33="N"),0, IF(A33="U", IF(OR(AC33="I-we",AC33="I-ca",AC33="F"),"**I", IF(Y33>=R$23,"C", IF(Y33>=S$23,"C-","**D"))), IF(A33="PF", IF(OR(AC33="I-we",AC33="I-ca",AC33="F"),AC33, IF(Y33>=R$23,"C", IF(Y33>=S$23,"C-","**D"))), IF(A33="PI-ca",IF(AC33="I-we","DATA",IF(AC33="I-ca",AC33, IF(Y33>=R$23,"C", IF(Y33>=S$23,"C-",IF(Y33>=T$23,"D","DATA"))))),IF(A33="PI-we", IF(AC33="I-ca","DATA",IF(AC33="I-we",AC33,IF(Y33>=R$23,"C", IF(Y33>=S$23,"C-",IF(Y33>=T$23,"D","DATA")))) ))) ))) -> 0 | AC33: =IF(AND(H33>=$D$15*$H$24,G33>=$D$15*$G$24),IF(F33>=$O$23,IF(F33>=$K$23,"A+",IF(F33>=$L$23,"A",IF(F33>=$M$23,"A-",IF(F33>=$N$23,"B+","B")))),IF(F33<$T$23,"I",IF(F33<$S$23,"D",IF(F33<$R$23,"C-",IF(F33<$Q$23,"C",IF(F33<$P$23,"C+",IF(F33<$O$23,"B-","B"))))))),IF(AND(H33<$D$15*$H$24,G33<$D$15*$G$24),"F",IF(H33<$D$15*$H$24,"I-ca","I-we"))) -> A
B34: ='Detailed Marks'!A13 -> 210035A | C34: ='Detailed Marks'!B13 -> AMARASINGHE Y.W.S.P. | E34: =+IF(AND(C34="",B34=""),"",IF(AA34=0,AC34,AA34)) -> A | F34: =G34+H34 -> 80.97 | G34: ='Detailed Marks'!L13/'Detailed Marks'!$L$3*'Final Marks'!$G$24 -> 25.8 | H34: =I34*H$24/I$24 -> 55.17 | I34: ='Detailed Marks'!M13 -> 55.17 | J34: =IF(I34/$I$24>=75,1,"") -> 1 | K34: =IF($D34="",IF($E34=K$24,1,0),IF($D34=K$24,1,0)) -> 0 | L34: =IF($D34="",IF($E34=L$24,1,0),IF($D34=L$24,1,0)) -> 1 | M34: =IF($D34="",IF($E34=M$24,1,0),IF($D34=M$24,1,0)) -> 0 | N34: =IF($D34="",IF($E34=N$24,1,0),IF($D34=N$24,1,0)) -> 0 | O34: =IF($D34="",IF($E34=O$24,1,0),IF($D34=O$24,1,0)) -> 0 | P34: =IF($D34="",IF($E34=P$24,1,0),IF($D34=P$24,1,0)) -> 0 | Q34: =IF($D34="",IF($E34=Q$24,1,0),IF($D34=Q$24,1,0)) -> 0 | R34: =IF($D34="",IF($E34=R$24,1,0),IF($D34=R$24,1,0)) -> 0 | ... T34: =IF($D34="",IF($E34=T$24,1,0),IF($D34=T$24,1,0)) -> 0 | U34: =IF($D34="",IF(LEFT($E34,1)=U$24,1,0),IF(LEFT($D34,1)=U$24,1,0)) -> 0 | V34: =IF($D34="",IF($E34=V$24,1,0),IF($D34=V$24,1,0)) -> 0 | W34: =IF($D34="",IF($E34=W$24,1,0),IF($D34=W$24,1,0)) -> 0 | Y34: =F34 -> 80.97 | AA34: =+IF(OR(A34="",A34="N"),0, IF(A34="U", IF(OR(AC34="I-we",AC34="I-ca",AC34="F"),"**I", IF(Y34>=R$23,"C", IF(Y34>=S$23,"C-","**D"))), IF(A34="PF", IF(OR(AC34="I-we",AC34="I-ca",AC34="F"),AC34, IF(Y34>=R$23,"C", IF(Y34>=S$23,"C-","**D"))), IF(A34="PI-ca",IF(AC34="I-we","DATA",IF(AC34="I-ca",AC34, IF(Y34>=R$23,"C", IF(Y34>=S$23,"C-",IF(Y34>=T$23,"D","DATA"))))),IF(A34="PI-we", IF(AC34="I-ca","DATA",IF(AC34="I-we",AC34,IF(Y34>=R$23,"C", IF(Y34>=S$23,"C-",IF(Y34>=T$23,"D","DATA")))) ))) ))) -> 0 | AC34: =IF(AND(H34>=$D$15*$H$24,G34>=$D$15*$G$24),IF(F34>=$O$23,IF(F34>=$K$23,"A+",IF(F34>=$L$23,"A",IF(F34>=$M$23,"A-",IF(F34>=$N$23,"B+","B")))),IF(F34<$T$23,"I",IF(F34<$S$23,"D",IF(F34<$R$23,"C-",IF(F34<$Q$23,"C",IF(F34<$P$23,"C+",IF(F34<$O$23,"B-","B"))))))),IF(AND(H34<$D$15*$H$24,G34<$D$15*$G$24),"F",IF(H34<$D$15*$H$24,"I-ca","I-we"))) -> A
B35: ='Detailed Marks'!A14 -> 210036D | C35: ='Detailed Marks'!B14 -> AMARASURIYA G.N. | E35: =+IF(AND(C35="",B35=""),"",IF(AA35=0,AC35,AA35)) -> A- | F35: =G35+H35 -> 72.89 | G35: ='Detailed Marks'!L14/'Detailed Marks'!$L$3*'Final Marks'!$G$24 -> 19.6 | H35: =I35*H$24/I$24 -> 53.29 | I35: ='Detailed Marks'!M14 -> 53.29 | J35: =IF(I35/$I$24>=75,1,"") -> 1 | K35: =IF($D35="",IF($E35=K$24,1,0),IF($D35=K$24,1,0)) -> 0 | L35: =IF($D35="",IF($E35=L$24,1,0),IF($D35=L$24,1,0)) -> 0 | M35: =IF($D35="",IF($E35=M$24,1,0),IF($D35=M$24,1,0)) -> 1 | N35: =IF($D35="",IF($E35=N$24,1,0),IF($D35=N$24,1,0)) -> 0 | O35: =IF($D35="",IF($E35=O$24,1,0),IF($D35=O$24,1,0)) -> 0 | P35: =IF($D35="",IF($E35=P$24,1,0),IF($D35=P$24,1,0)) -> 0 | Q35: =IF($D35="",IF($E35=Q$24,1,0),IF($D35=Q$24,1,0)) -> 0 | R35: =IF($D35="",IF($E35=R$24,1,0),IF($D35=R$24,1,0)) -> 0 | ... T35: =IF($D35="",IF($E35=T$24,1,0),IF($D35=T$24,1,0)) -> 0 | U35: =IF($D35="",IF(LEFT($E35,1)=U$24,1,0),IF(LEFT($D35,1)=U$24,1,0)) -> 0 | V35: =IF($D35="",IF($E35=V$24,1,0),IF($D35=V$24,1,0)) -> 0 | W35: =IF($D35="",IF($E35=W$24,1,0),IF($D35=W$24,1,0)) -> 0 | Y35: =F35 -> 72.89 | AA35: =+IF(OR(A35="",A35="N"),0, IF(A35="U", IF(OR(AC35="I-we",AC35="I-ca",AC35="F"),"**I", IF(Y35>=R$23,"C", IF(Y35>=S$23,"C-","**D"))), IF(A35="PF", IF(OR(AC35="I-we",AC35="I-ca",AC35="F"),AC35, IF(Y35>=R$23,"C", IF(Y35>=S$23,"C-","**D"))), IF(A35="PI-ca",IF(AC35="I-we","DATA",IF(AC35="I-ca",AC35, IF(Y35>=R$23,"C", IF(Y35>=S$23,"C-",IF(Y35>=T$23,"D","DATA"))))),IF(A35="PI-we", IF(AC35="I-ca","DATA",IF(AC35="I-we",AC35,IF(Y35>=R$23,"C", IF(Y35>=S$23,"C-",IF(Y35>=T$23,"D","DATA")))) ))) ))) -> 0 | AC35: =IF(AND(H35>=$D$15*$H$24,G35>=$D$15*$G$24),IF(F35>=$O$23,IF(F35>=$K$23,"A+",IF(F35>=$L$23,"A",IF(F35>=$M$23,"A-",IF(F35>=$N$23,"B+","B")))),IF(F35<$T$23,"I",IF(F35<$S$23,"D",IF(F35<$R$23,"C-",IF(F35<$Q$23,"C",IF(F35<$P$23,"C+",IF(F35<$O$23,"B-","B"))))))),IF(AND(H35<$D$15*$H$24,G35<$D$15*$G$24),"F",IF(H35<$D$15*$H$24,"I-ca","I-we"))) -> A-
B36: ='Detailed Marks'!A15 -> 210037G | C36: ='Detailed Marks'!B15 -> AMARATHUNGA D.N. | E36: =+IF(AND(C36="",B36=""),"",IF(AA36=0,AC36,AA36)) -> A- | F36: =G36+H36 -> 72.17 | G36: ='Detailed Marks'!L15/'Detailed Marks'!$L$3*'Final Marks'!$G$24 -> 19 | H36: =I36*H$24/I$24 -> 53.17 | I36: ='Detailed Marks'!M15 -> 53.17 | J36: =IF(I36/$I$24>=75,1,"") -> 1 | K36: =IF($D36="",IF($E36=K$24,1,0),IF($D36=K$24,1,0)) -> 0 | L36: =IF($D36="",IF($E36=L$24,1,0),IF($D36=L$24,1,0)) -> 0 | M36: =IF($D36="",IF($E36=M$24,1,0),IF($D36=M$24,1,0)) -> 1 | N36: =IF($D36="",IF($E36=N$24,1,0),IF($D36=N$24,1,0)) -> 0 | O36: =IF($D36="",IF($E36=O$24,1,0),IF($D36=O$24,1,0)) -> 0 | P36: =IF($D36="",IF($E36=P$24,1,0),IF($D36=P$24,1,0)) -> 0 | Q36: =IF($D36="",IF($E36=Q$24,1,0),IF($D36=Q$24,1,0)) -> 0 | R36: =IF($D36="",IF($E36=R$24,1,0),IF($D36=R$24,1,0)) -> 0 | ... T36: =IF($D36="",IF($E36=T$24,1,0),IF($D36=T$24,1,0)) -> 0 | U36: =IF($D36="",IF(LEFT($E36,1)=U$24,1,0),IF(LEFT($D36,1)=U$24,1,0)) -> 0 | V36: =IF($D36="",IF($E36=V$24,1,0),IF($D36=V$24,1,0)) -> 0 | W36: =IF($D36="",IF($E36=W$24,1,0),IF($D36=W$24,1,0)) -> 0 | Y36: =F36 -> 72.17 | AA36: =+IF(OR(A36="",A36="N"),0, IF(A36="U", IF(OR(AC36="I-we",AC36="I-ca",AC36="F"),"**I", IF(Y36>=R$23,"C", IF(Y36>=S$23,"C-","**D"))), IF(A36="PF", IF(OR(AC36="I-we",AC36="I-ca",AC36="F"),AC36, IF(Y36>=R$23,"C", IF(Y36>=S$23,"C-","**D"))), IF(A36="PI-ca",IF(AC36="I-we","DATA",IF(AC36="I-ca",AC36, IF(Y36>=R$23,"C", IF(Y36>=S$23,"C-",IF(Y36>=T$23,"D","DATA"))))),IF(A36="PI-we", IF(AC36="I-ca","DATA",IF(AC36="I-we",AC36,IF(Y36>=R$23,"C", IF(Y36>=S$23,"C-",IF(Y36>=T$23,"D","DATA")))) ))) ))) -> 0 | AC36: =IF(AND(H36>=$D$15*$H$24,G36>=$D$15*$G$24),IF(F36>=$O$23,IF(F36>=$K$23,"A+",IF(F36>=$L$23,"A",IF(F36>=$M$23,"A-",IF(F36>=$N$23,"B+","B")))),IF(F36<$T$23,"I",IF(F36<$S$23,"D",IF(F36<$R$23,"C-",IF(F36<$Q$23,"C",IF(F36<$P$23,"C+",IF(F36<$O$23,"B-","B"))))))),IF(AND(H36<$D$15*$H$24,G36<$D$15*$G$24),"F",IF(H36<$D$15*$H$24,"I-ca","I-we"))) -> A-
... B125: ='Detailed Marks'!A104 -> 210732H | C125: ='Detailed Marks'!B104 -> WITHANAWASAM I.A. | E125: =+IF(AND(C125="",B125=""),"",IF(AA125=0,AC125,AA125)) -> A | F125: =G125+H125 -> 77.23 | G125: ='Detailed Marks'!L104/'Detailed Marks'!$L$3*'Final Marks'!$G$24 -> 23.6 | H125: =I125*H$24/I$24 -> 53.63 | I125: ='Detailed Marks'!M104 -> 53.63 | J125: =IF(I125/$I$24>=75,1,"") -> 1 | K125: =IF($D125="",IF($E125=K$24,1,0),IF($D125=K$24,1,0)) -> 0 | L125: =IF($D125="",IF($E125=L$24,1,0),IF($D125=L$24,1,0)) -> 1 | M125: =IF($D125="",IF($E125=M$24,1,0),IF($D125=M$24,1,0)) -> 0 | N125: =IF($D125="",IF($E125=N$24,1,0),IF($D125=N$24,1,0)) -> 0 | O125: =IF($D125="",IF($E125=O$24,1,0),IF($D125=O$24,1,0)) -> 0 | P125: =IF($D125="",IF($E125=P$24,1,0),IF($D125=P$24,1,0)) -> 0 | Q125: =IF($D125="",IF($E125=Q$24,1,0),IF($D125=Q$24,1,0)) -> 0 | R125: =IF($D125="",IF($E125=R$24,1,0),IF($D125=R$24,1,0)) -> 0 | ... T125: =IF($D125="",IF($E125=T$24,1,0),IF($D125=T$24,1,0)) -> 0 | U125: =IF($D125="",IF(LEFT($E125,1)=U$24,1,0),IF(LEFT($D125,1)=U$24,1,0)) -> 0 | V125: =IF($D125="",IF($E125=V$24,1,0),IF($D125=V$24,1,0)) -> 0 | W125: =IF($D125="",IF($E125=W$24,1,0),IF($D125=W$24,1,0)) -> 0 | Y125: =F125 -> 77.23 | AA125: =+IF(OR(A125="",A125="N"),0, IF(A125="U", IF(OR(AC125="I-we",AC125="I-ca",AC125="F"),"**I", IF(Y125>=R$23,"C", IF(Y125>=S$23,"C-","**D"))), IF(A125="PF", IF(OR(AC125="I-we",AC125="I-ca",AC125="F"),AC125, IF(Y125>=R$23,"C", IF(Y125>=S$23,"C-","**D"))), IF(A125="PI-ca",IF(AC125="I-we","DATA",IF(AC125="I-ca",AC125, IF(Y125>=R$23,"C", IF(Y125>=S$23,"C-",IF(Y125>=T$23,"D","DATA"))))),IF(A125="PI-we", IF(AC125="I-ca","DATA",IF(AC125="I-we",AC125,IF(Y125>=R$23,"C", IF(Y125>=S$23,"C-",IF(Y125>=T$23,"D","DATA")))) ))) ))) -> 0 | AC125: =IF(AND(H125>=$D$15*$H$24,G125>=$D$15*$G$24),IF(F125>=$O$23,IF(F125>=$K$23,"A+",IF(F125>=$L$23,"A",IF(F125>=$M$23,"A-",IF(F125>=$N$23,"B+","B")))),IF(F125<$T$23,"I",IF(F125<$S$23,"D",IF(F125<$R$23,"C-",IF(F125<$Q$23,"C",IF(F125<$P$23,"C+",IF(F125<$O$23,"B-","B"))))))),IF(AND(H125<$D$15*$H$24,G125<$D$15*$G$24),"F",IF(H125<$D$15*$H$24,"I-ca","I-we"))) -> A
B127: N - | C127: Academic concession
B128: PF - | C128: Previous attempt - Fail
B129: PI - | C129: Previous attempt - Incomplete
B130: U - | C130: Upgrade
...

Sheet Detailed Marks
A1: Module Code :EN4554 | C1: Module : Deep Learning for Vision
A2: Index No | B2: Name | E2: Detail Marks of Exam | L2: Exam Total | M2: Continous Assessment
C3: 1 | D3: 2 | E3: 3 | F3: 4 | L3: 1 | M3: 0.6
A4: ='EN4554_Intake 2021_New BSc Eng.'!A2 -> 200370K | B4: ='EN4554_Intake 2021_New BSc Eng.'!B2 -> MADUWANTHA L.H.H. | C4: 19 | D4: 20 | E4: 7 | F4: 8 | G4: 12.5 | L4: =SUM(C4:K4) -> 66.5 | M4: =VLOOKUP($A4, Moodle!$D$2:$V$102, 19, FALSE) -> 48.42
A5: ='EN4554_Intake 2021_New BSc Eng.'!A3 -> 210003B | B5: ='EN4554_Intake 2021_New BSc Eng.'!B3 -> ABEWICKREMA A.S.J. | C5: 20 | D5: 13 | E5: 8 | F5: 5 | G5: 12.5 | L5: =SUM(C5:K5) -> 58.5 | M5: =VLOOKUP($A5, Moodle!$D$2:$V$102, 19, FALSE) -> 51.17
A6: ='EN4554_Intake 2021_New BSc Eng.'!A4 -> 210005H | B6: ='EN4554_Intake 2021_New BSc Eng.'!B4 -> ABEYRATHNA S.M.S.M.B. | C6: 12.5 | D6: 11 | E6: 11 | F6: 4 | G6: 12.5 | L6: =SUM(C6:K6) -> 51 | M6: =VLOOKUP($A6, Moodle!$D$2:$V$102, 19, FALSE) -> 51.25
A7: ='EN4554_Intake 2021_New BSc Eng.'!A5 -> 210014J | B7: ='EN4554_Intake 2021_New BSc Eng.'!B5 -> ABEYWARDANA K.D.W. | C7: 14 | D7: 10 | E7: 6 | F7: 14 | G7: 12.5 | L7: =SUM(C7:K7) -> 56.5 | M7: =VLOOKUP($A7, Moodle!$D$2:$V$102, 19, FALSE) -> 52.08
A8: ='EN4554_Intake 2021_New BSc Eng.'!A6 -> 210019E | B8: ='EN4554_Intake 2021_New BSc Eng.'!B6 -> ABITHAN A. | C8: 8.5 | D8: 11 | E8: 4 | F8: 6 | G8: 12.5 | L8: =SUM(C8:K8) -> 42 | M8: =VLOOKUP($A8, Moodle!$D$2:$V$102, 19, FALSE) -> 49.33
A9: ='EN4554_Intake 2021_New BSc Eng.'!A7 -> 210021D | B9: ='EN4554_Intake 2021_New BSc Eng.'!B7 -> ADIKARAM W.K.D.N.E. | C9: 12 | D9: 5 | E9: 8 | F9: 6 | G9: 12.5 | L9: =SUM(C9:K9) -> 43.5 | M9: =VLOOKUP($A9, Moodle!$D$2:$V$102, 19, FALSE) -> 48.88
A10: ='EN4554_Intake 2021_New BSc Eng.'!A8 -> 210022G | B10: ='EN4554_Intake 2021_New BSc Eng.'!B8 -> ADIKARI A.A.S.D. | C10: 17.5 | D10: 21 | E10: 14 | F10: 8 | G10: 12.5 | L10: =SUM(C10:K10) -> 73 | M10: =VLOOKUP($A10, Moodle!$D$2:$V$102, 19, FALSE) -> 53.17
A11: ='EN4554_Intake 2021_New BSc Eng.'!A9 -> 210027C | B11: ='EN4554_Intake 2021_New BSc Eng.'!B9 -> ALAHAKOON U.M.Y.B. | C11: 14.5 | D11: 18 | E11: 8 | F11: 13 | G11: 12.5 | L11: =SUM(C11:K11) -> 66 | M11: =VLOOKUP($A11, Moodle!$D$2:$V$102, 19, FALSE) -> 48.77
A12: ='EN4554_Intake 2021_New BSc Eng.'!A10 -> 210031H | B12: ='EN4554_Intake 2021_New BSc Eng.'!B10 -> AMARASINGHE A.A.W.L.R. | C12: 11 | D12: 17 | E12: 15 | F12: 7 | G12: 12.5 | L12: =SUM(C12:K12) -> 62.5 | M12: =VLOOKUP($A12, Moodle!$D$2:$V$102, 19, FALSE) -> 55.25
A13: ='EN4554_Intake 2021_New BSc Eng.'!A11 -> 210035A | B13: ='EN4554_Intake 2021_New BSc Eng.'!B11 -> AMARASINGHE Y.W.S.P. | C13: 15 | D13: 13 | E13: 16 | F13: 8 | G13: 12.5 | L13: =SUM(C13:K13) -> 64.5 | M13: =VLOOKUP($A13, Moodle!$D$2:$V$102, 19, FALSE) -> 55.17
A14: ='EN4554_Intake 2021_New BSc Eng.'!A12 -> 210036D | B14: ='EN4554_Intake 2021_New BSc Eng.'!B12 -> AMARASURIYA G.N. | C14: 11.5 | D14: 6 | E14: 8 | F14: 11 | G14: 12.5 | L14: =SUM(C14:K14) -> 49 | M14: =VLOOKUP($A14, Moodle!$D$2:$V$102, 19, FALSE) -> 53.29
A15: ='EN4554_Intake 2021_New BSc Eng.'!A13 -> 210037G | B15: ='EN4554_Intake 2021_New BSc Eng.'!B13 -> AMARATHUNGA D.N. | C15: 11 | D15: 8 | E15: 10 | F15: 6 | G15: 12.5 | L15: =SUM(C15:K15) -> 47.5 | M15: =VLOOKUP($A15, Moodle!$D$2:$V$102, 19, FALSE) -> 53.17
... A19: ='EN4554_Intake 2021_New BSc Eng.'!A17 -> 210075U | B19: ='EN4554_Intake 2021_New BSc Eng.'!B17 -> CHANDRAJITH B.P.L. | C19: 16.5 | D19: 18 | E19: 5 | F19: 4 | G19: 12.5 | L19: =SUM(C19:K19) -> 56 | M19: =VLOOKUP($A19, Moodle!$D$2:$V$102, 19, FALSE) -> 52.25
A20: ='EN4554_Intake 2021_New BSc Eng.'!A18 -> 210088L | B20: ='EN4554_Intake 2021_New BSc Eng.'!B18 -> COORAY P.L.L.K. | C20: 11.5 | D20: 5 | E20: 2 | F20: 9 | G20: 12.5 | H20: 0.2 | L20: =SUM(C20:K20) -> 40.2 | M20: =VLOOKUP($A20, Moodle!$D$2:$V$102, 19, FALSE) -> 53.42
A21: ='EN4554_Intake 2021_New BSc Eng.'!A19 -> 210089P | B21: ='EN4554_Intake 2021_New BSc Eng.'!B19 -> DABARE A.D.T. | C21: 15 | D21: 20 | E21: 13 | F21: 11 | G21: 12.5 | L21: =SUM(C21:K21) -> 71.5 | M21: =VLOOKUP($A21, Moodle!$D$2:$V$102, 19, FALSE) -> 50.29
A22: ='EN4554_Intake 2021_New BSc Eng.'!A20 -> 210095F | B22: ='EN4554_Intake 2021_New BSc Eng.'!B20 -> DASSANAYAKE D.M.T.K.R. | C22: 15 | D22: 17 | E22: 8 | F22: 10 | G22: 12.5 | L22: =SUM(C22:K22) -> 62.5 | M22: =VLOOKUP($A22, Moodle!$D$2:$V$102, 19, FALSE) -> 50.08
A23: ='EN4554_Intake 2021_New BSc Eng.'!A21 -> 210097M | B23: ='EN4554_Intake 2021_New BSc Eng.'!B21 -> DE SILVA A.N.T. | C23: 6 | D23: 3 | E23: 6 | F23: 9 | G23: 12.5 | L23: =SUM(C23:K23) -> 36.5 | M23: =VLOOKUP($A23, Moodle!$D$2:$V$102, 19, FALSE) -> 39.96
A24: ='EN4554_Intake 2021_New BSc Eng.'!A22 -> 210108C | B24: ='EN4554_Intake 2021_New BSc Eng.'!B22 -> DE ZOYSA A.K.N. | C24: 13.5 | D24: 12 | E24: 5 | F24: 4 | G24: 12.5 | L24: =SUM(C24:K24) -> 47 | M24: =VLOOKUP($A24, Moodle!$D$2:$V$102, 19, FALSE) -> 50.05
A25: ='EN4554_Intake 2021_New BSc Eng.'!A23 -> 210121J | B25: ='EN4554_Intake 2021_New BSc Eng.'!B23 -> DHARMADASA W.H.M.A.D. | C25: 10 | D25: 5 | E25: 6 | F25: 5 | G25: 12.5 | L25: =SUM(C25:K25) -> 38.5 | M25: =VLOOKUP($A25, Moodle!$D$2:$V$102, 19, FALSE) -> 36.04
A26: ='EN4554_Intake 2021_New BSc Eng.'!A24 -> 210130K | B26: ='EN4554_Intake 2021_New BSc Eng.'!B24 -> DILUSHANA H.M.P.S. | C26: 11.5 | D26: 5 | E26: 5 | F26: 3 | G26: 12.5 | L26: =SUM(C26:K26) -> 37 | M26: =VLOOKUP($A26, Moodle!$D$2:$V$102, 19, FALSE) -> 35.83
A27: ='EN4554_Intake 2021_New BSc Eng.'!A25 -> 210131N | B27: ='EN4554_Intake 2021_New BSc Eng.'!B25 -> DIMAGI D.H.P. | C27: 15 | D27: 18 | E27: 6 | F27: 17 | G27: 12.5 | L27: =SUM(C27:K27) -> 68.5 | M27: =VLOOKUP($A27, Moodle!$D$2:$V$102, 19, FALSE) -> 55.75
A28: ='EN4554_Intake 2021_New BSc Eng.'!A26 -> 210140P | B28: ='EN4554_Intake 2021_New BSc Eng.'!B26 -> DISSANAYAKA D.M.P.C. | C28: 15 | D28: 14 | E28: 8 | F28: 8 | G28: 12.5 | L28: =SUM(C28:K28) -> 57.5 | M28: =VLOOKUP($A28, Moodle!$D$2:$V$102, 19, FALSE) -> 50.75
A29: ='EN4554_Intake 2021_New BSc Eng.'!A27 -> 210141U | B29: ='EN4554_Intake 2021_New BSc Eng.'!B27 -> DISSANAYAKA D.M.S.P. | C29: 19.5 | D29: 13 | E29: 7 | F29: 2 | G29: 12.5 | L29: =SUM(C29:K29) -> 54 | M29: =VLOOKUP($A29, Moodle!$D$2:$V$102, 19, FALSE) -> 52.29
A30: ='EN4554_Intake 2021_New BSc Eng.'!A28 -> 210147T | B30: ='EN4554_Intake 2021_New BSc Eng.'!B28 -> DISSANAYAKE D.M.S.D. | C30: 10 | D30: 4 | E30: 6 | F30: 4 | G30: 12.5 | L30: =SUM(C30:K30) -> 36.5 | M30: =VLOOKUP($A30, Moodle!$D$2:$V$102, 19, FALSE) -> 42.54
A31: ='EN4554_Intake 2021_New BSc Eng.'!A29 -> 210150V | B31: ='EN4554_Intake 2021_New BSc Eng.'!B29 -> DODANGODA D.K.S.J. | C31: 8 | D31: 11 | E31: 10 | F31: 6 | G31: 12.5 | L31: =SUM(C31:K31) -> 47.5 | M31: =VLOOKUP($A31, Moodle!$D$2:$V$102, 19, FALSE) -> 47.05
A32: ='EN4554_Intake 2021_New BSc Eng.'!A30 -> 210152E | B32: ='EN4554_Intake 2021_New BSc Eng.'!B30 -> DULNATH W.H.R. | C32: 16.5 | D32: 3 | E32: 6 | F32: 3 | G32: 12.5 | H32: 0.3 | L32: =SUM(C32:K32) -> 41.3 | M32: =VLOOKUP($A32, Moodle!$D$2:$V$102, 19, FALSE) -> 43
A33: ='EN4554_Intake 2021_New BSc Eng.'!A31 -> 210153H | B33: ='EN4554_Intake 2021_New BSc Eng.'!B31 -> EDIRISINGHE E.A.D.D.D. | C33: 19.5 | D33: 13 | E33: 4 | F33: 3 | G33: 12.5 | L33: =SUM(C33:K33) -> 52 | M33: =VLOOKUP($A33, Moodle!$D$2:$V$102, 19, FALSE) -> 52.21
A34: ='EN4554_Intake 2021_New BSc Eng.'!A32 -> 210156U | B34: ='EN4554_Intake 2021_New BSc Eng.'!B32 -> EPA Y.L.A. | C34: 15.5 | D34: 17 | E34: 6 | F34: 6 | G34: 12.5 | L34: =SUM(C34:K34) -> 57 | M34: =VLOOKUP($A34, Moodle!$D$2:$V$102, 19, FALSE) -> 54.25
A35: ='EN4554_Intake 2021_New BSc Eng.'!A33 -> 210157A | B35: ='EN4554_Intake 2021_New BSc Eng.'!B33 -> EPA Y.R.A. | C35: 15.5 | D35: 18 | E35: 12 | F35: 10 | G35: 12.5 | L35: =SUM(C35:K35) -> 68 | M35: =VLOOKUP($A35, Moodle!$D$2:$V$102, 19, FALSE) -> 56.25
A36: ='EN4554_Intake 2021_New BSc Eng.'!A34 -> 210162J | B36: ='EN4554_Intake 2021_New BSc Eng.'!B34 -> FERNANDO N.I.S.P. | C36: 6 | D36: 9 | E36: 5 | F36: 4 | G36: 12.5 | L36: =SUM(C36:K36) -> 36.5 | M36: =VLOOKUP($A36, Moodle!$D$2:$V$102, 19, FALSE) -> 37.75
A37: ='EN4554_Intake 2021_New BSc Eng.'!A35 -> 210169L | B37: ='EN4554_Intake 2021_New BSc Eng.'!B35 -> FERNANDO W.W.R.N.S. | C37: 20 | D37: 18 | E37: 5 | F37: 13 | G37: 12.5 | L37: =SUM(C37:K37) -> 68.5 | M37: =VLOOKUP($A37, Moodle!$D$2:$V$102, 19, FALSE) -> 51.46
A38: ='EN4554_Intake 2021_New BSc Eng.'!A36 -> 210174X | B38: ='EN4554_Intake 2021_New BSc Eng.'!B36 -> GALLELLA M.M.H.H.B. | C38: 19 | D38: 11 | E38: 17 | F38: 16 | G38: 12.5 | L38: =SUM(C38:K38) -> 75.5 | M38: =VLOOKUP($A38, Moodle!$D$2:$V$102, 19, FALSE) -> 58.79
A39: ='EN4554_Intake 2021_New BSc Eng.'!A37 -> 210179R | B39: ='EN4554_Intake 2021_New BSc Eng.'!B37 -> GAMMUNE D.J.T. | C39: 13.5 | D39: 15 | E39: 15 | F39: 12 | G39: 12.5 | L39: =SUM(C39:K39) -> 68 | M39: =VLOOKUP($A39, Moodle!$D$2:$V$102, 19, FALSE) -> 51.54
A40: ='EN4554_Intake 2021_New BSc Eng.'!A38 -> 210199D | B40: ='EN4554_Intake 2021_New BSc Eng.'!B38 -> GUNAWARDANA W.N.M. | C40: 14 | D40: 16 | E40: 8 | F40: 7 | G40: 12.5 | L40: =SUM(C40:K40) -> 57.5 | M40: =VLOOKUP($A40, Moodle!$D$2:$V$102, 19, FALSE) -> 49.38
A41: ='EN4554_Intake 2021_New BSc Eng.'!A39 -> 210200C | B41: ='EN4554_Intake 2021_New BSc Eng.'!B39 -> GUNAWARDANE E.R.N.H. | C41: 17.5 | D41: 16 | E41: 13 | F41: 11 | G41: 12.5 | L41: =SUM(C41:K41) -> 70 | M41: =VLOOKUP($A41, Moodle!$D$2:$V$102, 19, FALSE) -> 53.33
A42: ='EN4554_Intake 2021_New BSc Eng.'!A40 -> 210204R | B42: ='EN4554_Intake 2021_New BSc Eng.'!B40 -> HANSINDU K.A.A. | C42: 19 | D42: 14 | E42: 10 | F42: 5 | G42: 12.5 | L42: =SUM(C42:K42) -> 60.5 | M42: =VLOOKUP($A42, Moodle!$D$2:$V$102, 19, FALSE) -> 55.42
A43: ='EN4554_Intake 2021_New BSc Eng.'!A41 -> 210212N | B43: ='EN4554_Intake 2021_New BSc Eng.'!B41 -> HERATH B.H.M.K.S.B. | C43: 15.5 | D43: 17 | E43: 5 | F43: 17 | G43: 12.5 | L43: =SUM(C43:K43) -> 67 | M43: =VLOOKUP($A43, Moodle!$D$2:$V$102, 19, FALSE) -> 54
...

Sheet EN4554_Intake 2021_New BSc Eng.
A1: Registration Number | B1: Name With Initials | C1: WE (100%) | D1: CA (100%) | E1: Registered For
A2: 200370K | B2: MADUWANTHA L.H.H. | C2: ='Detailed Marks'!L4 -> 66.5 | D2: ='Detailed Marks'!M4/60*100 -> 80.7
A3: 210003B | B3: ABEWICKREMA A.S.J. | C3: ='Detailed Marks'!L5 -> 58.5 | D3: ='Detailed Marks'!M5/60*100 -> 85.283333
A4: 210005H | B4: ABEYRATHNA S.M.S.M.B. | C4: ='Detailed Marks'!L6 -> 51 | D4: ='Detailed Marks'!M6/60*100 -> 85.416667
A5: 210014J | B5: ABEYWARDANA K.D.W. | C5: ='Detailed Marks'!L7 -> 56.5 | D5: ='Detailed Marks'!M7/60*100 -> 86.8
A6: 210019E | B6: ABITHAN A. | C6: ='Detailed Marks'!L8 -> 42 | D6: ='Detailed Marks'!M8/60*100 -> 82.216667
A7: 210021D | B7: ADIKARAM W.K.D.N.E. | C7: ='Detailed Marks'!L9 -> 43.5 | D7: ='Detailed Marks'!M9/60*100 -> 81.466667
A8: 210022G | B8: ADIKARI A.A.S.D. | C8: ='Detailed Marks'!L10 -> 73 | D8: ='Detailed Marks'!M10/60*100 -> 88.616667
A9: 210027C | B9: ALAHAKOON U.M.Y.B. | C9: ='Detailed Marks'!L11 -> 66 | D9: ='Detailed Marks'!M11/60*100 -> 81.283333
A10: 210031H | B10: AMARASINGHE A.A.W.L.R. | C10: ='Detailed Marks'!L12 -> 62.5 | D10: ='Detailed Marks'!M12/60*100 -> 92.083333
A11: 210035A | B11: AMARASINGHE Y.W.S.P. | C11: ='Detailed Marks'!L13 -> 64.5 | D11: ='Detailed Marks'!M13/60*100 -> 91.95
A12: 210036D | B12: AMARASURIYA G.N. | C12: ='Detailed Marks'!L14 -> 49 | D12: ='Detailed Marks'!M14/60*100 -> 88.816667
A13: 210037G | B13: AMARATHUNGA D.N. | C13: ='Detailed Marks'!L15 -> 47.5 | D13: ='Detailed Marks'!M15/60*100 -> 88.616667
... A102: 210732H | B102: WITHANAWASAM I.A. | C102: ='Detailed Marks'!L104 -> 59 | D102: ='Detailed Marks'!M104/60*100 -> 89.383333

Sheet Marks Addition
A1: Module Code :EN1060 | C1: Module : Signals and Systems
A2: Index No | B2: Name | E2: Detail Marks of Exam | S2: Exam Total | T2: Sum
C3: 1a | D3: 1b | E3: 1c | F3: 1d | G3: 2a | H3: 2b | I3: 2c | J3: 2d | K3: 3a | L3: 3b | M3: 3c | N3: 3d | O3: 4a | P3: 4b | Q3: 4c | R3: 4d | S3: 1
A4: ='Detailed Marks'!A4 -> 200370K | B4: ='Detailed Marks'!B4 -> MADUWANTHA L.H.H. | C4: 3 | D4: 3 | E4: 8 | F4: 5 | G4: 9 | H4: 4 | I4: 3 | J4: 4 | K4: 1 | L4: 4 | M4: 1 | N4: 1 | O4: 5 | P4: 2 | Q4: 1 | R4: 0 | S4: =SUM(C4:R4) -> 54 | T4: ='Detailed Marks'!L4 -> 66.5
A5: ='Detailed Marks'!A5 -> 210003B | B5: ='Detailed Marks'!B5 -> ABEWICKREMA A.S.J. | C5: 2 | D5: 4 | E5: 8 | F5: 6 | G5: 8 | H5: 1 | I5: 2 | J5: 2 | K5: 0 | L5: 8 | M5: 0 | N5: 0 | O5: 3 | P5: 2 | Q5: 0 | R5: 0 | S5: =SUM(C5:R5) -> 46 | T5: ='Detailed Marks'!L5 -> 58.5
A6: ='Detailed Marks'!A6 -> 210005H | B6: ='Detailed Marks'!B6 -> ABEYRATHNA S.M.S.M.B. | C6: 3.5 | D6: 0 | E6: 3 | F6: 6 | G6: 5 | H6: 1 | I6: 2 | J6: 3 | K6: 2 | L6: 8 | M6: 1 | N6: 0 | O6: 1 | P6: 3 | Q6: 0 | R6: 0 | S6: =SUM(C6:R6) -> 38.5 | T6: ='Detailed Marks'!L6 -> 51
A7: ='Detailed Marks'!A7 -> 210014J | B7: ='Detailed Marks'!B7 -> ABEYWARDANA K.D.W. | C7: 3 | D7: 3 | E7: 4 | F7: 4 | G7: 1 | H7: 5 | I7: 2 | J7: 2 | K7: 3 | L7: 0 | M7: 1 | N7: 2 | O7: 3 | P7: 5 | Q7: 3 | R7: 3 | S7: =SUM(C7:R7) -> 44 | T7: ='Detailed Marks'!L7 -> 56.5
A8: ='Detailed Marks'!A8 -> 210019E | B8: ='Detailed Marks'!B8 -> ABITHAN A. | C8: 0.5 | D8: 0 | E8: 4 | F8: 4 | G8: 4 | H8: 2 | I8: 2 | J8: 3 | K8: 1 | L8: 2 | M8: 0 | N8: 1 | O8: 2 | P8: 3 | Q8: 1 | R8: 0 | S8: =SUM(C8:R8) -> 29.5 | T8: ='Detailed Marks'!L8 -> 42
A9: ='Detailed Marks'!A9 -> 210021D | B9: ='Detailed Marks'!B9 -> ADIKARAM W.K.D.N.E. | C9: 3 | D9: 2 | E9: 3 | F9: 4 | G9: 0 | H9: 3 | I9: 0 | J9: 2 | K9: 4 | L9: 0 | M9: 2 | N9: 2 | O9: 3 | P9: 2 | Q9: 1 | R9: 0 | S9: =SUM(C9:R9) -> 31 | T9: ='Detailed Marks'!L9 -> 43.5
A10: ='Detailed Marks'!A10 -> 210022G | B10: ='Detailed Marks'!B10 -> ADIKARI A.A.S.D. | C10: 1.5 | D10: 5 | E10: 7 | F10: 4 | G10: 9 | H10: 6 | I10: 3 | J10: 3 | K10: 4 | L10: 6 | M10: 2 | N10: 2 | O10: 2 | P10: 2 | Q10: 3 | R10: 1 | S10: =SUM(C10:R10) -> 60.5 | T10: ='Detailed Marks'!L10 -> 73
A11: ='Detailed Marks'!A11 -> 210027C | B11: ='Detailed Marks'!B11 -> ALAHAKOON U.M.Y.B. | C11: 1.5 | D11: 2 | E11: 7 | F11: 4 | G11: 8 | H11: 6 | I11: 2 | J11: 2 | K11: 2 | L11: 1 | M11: 1 | N11: 4 | O11: 3 | P11: 6 | Q11: 3 | R11: 1 | S11: =SUM(C11:R11) -> 53.5 | T11: ='Detailed Marks'!L11 -> 66
A12: ='Detailed Marks'!A12 -> 210031H | B12: ='Detailed Marks'!B12 -> AMARASINGHE A.A.W.L.R. | C12: 2 | D12: 0 | E12: 5 | F12: 4 | G12: 9 | H12: 2 | I12: 2 | J12: 4 | K12: 3 | L12: 6 | M12: 2 | N12: 4 | O12: 3 | P12: 3 | Q12: 1 | R12: 0 | S12: =SUM(C12:R12) -> 50 | T12: ='Detailed Marks'!L12 -> 62.5
A13: ='Detailed Marks'!A13 -> 210035A | B13: ='Detailed Marks'!B13 -> AMARASINGHE Y.W.S.P. | C13: 2 | D13: 4 | E13: 5 | F13: 4 | G13: 9 | H13: 0 | I13: 2 | J13: 2 | K13: 2 | L13: 6 | M13: 4 | N13: 4 | O13: 2 | P13: 3 | Q13: 2 | R13: 1 | S13: =SUM(C13:R13) -> 52 | T13: ='Detailed Marks'!L13 -> 64.5
A14: ='Detailed Marks'!A14 -> 210036D | B14: ='Detailed Marks'!B14 -> AMARASURIYA G.N. | C14: 1.5 | D14: 0 | E14: 5 | F14: 5 | G14: 0 | H14: 3 | I14: 2 | J14: 1 | K14: 3 | L14: 0 | M14: 1 | N14: 4 | O14: 3 | P14: 3 | Q14: 3 | R14: 2 | S14: =SUM(C14:R14) -> 36.5 | T14: ='Detailed Marks'!L14 -> 49
A15: ='Detailed Marks'!A15 -> 210037G | B15: ='Detailed Marks'!B15 -> AMARATHUNGA D.N. | C15: 0 | D15: 2 | E15: 5 | F15: 4 | G15: 0 | H15: 3 | I15: 2 | J15: 3 | K15: 2 | L15: 4 | M15: 1 | N15: 3 | O15: 2 | P15: 3 | Q15: 1 | R15: 0 | S15: =SUM(C15:R15) -> 35 | T15: ='Detailed Marks'!L15 -> 47.5
... A104: ='Detailed Marks'!A104 -> 210732H | B104: ='Detailed Marks'!B104 -> WITHANAWASAM I.A. | C104: 1.5 | D104: 2 | E104: 5 | F104: 5 | G104: 5 | H104: 4 | I104: 3 | J104: 4 | K104: 2 | L104: 2 | M104: 1 | N104: 4 | O104: 4 | P104: 2 | Q104: 0 | R104: 2 | S104: =SUM(C104:R104) -> 46.5 | T104: ='Detailed Marks'!L104 -> 59

Sheet Moodle
A1: Name with Initials | B1: Last name | C1: ID number | D1: Institution | E1: Department | F1: Email address | G1: Quiz: Q01 on Introduction (Real) | H1: Quiz: Q02 Image Classification (Real) | I1: Quiz: Q03 Convolutional Neural Networks (Real) | J1: Quiz: Q04 Linear Networks (Real) | K1: Quiz: Q06 Backpropagation (Real) | L1: Quiz: Q09 Object Detection (Real) | M1: Quiz: Q10 Attention in Vision (Real) | N1: Quiz: Q11 Image Segmentation (Real) | O1: Quiz: Q12 Vision Language Models (Real) | P1: Quiz: Q13 Diffusion Models (Real) | Q1: Quizzes total (Real) | R1: Mid Semester Exam (Real) | S1: Paper Presentation (Real) | T1: Project Final (Real) | U1: Project total (Real) | V1: Course total (Real) | W1: Last downloaded from this course
A2: MADUWANTHA L.H.H. | B2: 200370K | C2: 35333 | D2: 200370K | F2: maduwanthalhh.20@uom.lk | G2: - | H2: 10 | I2: 9 | J2: 1 | K2: 10 | L2: 9 | M2: 9 | N2: 10 | O2: 9.17 | P2: 10 | Q2: 9.65 | R2: 12 | S2: 4.5 | T2: 12.63 | U2: 17.13 | V2: 48.42 | W2: 1766912722
A3: ABEWICKREMA A.S.J. | B3: 210003B | C3: 39236 | D3: 210003B | F3: abewickremaasj.21@uom.lk | G3: 9 | H3: 10 | I3: 10 | J3: - | K3: 10 | L3: 9 | M3: 9.5 | N3: 9.67 | O3: 8 | P3: 10 | Q3: 9.65 | R3: 20 | S3: 2 | T3: 9.88 | U3: 11.88 | V3: 51.17 | W3: 1766912722
A4: ABEYRATHNA S.M.S.M.B. | B4: 210005H | C4: 39238 | D4: 210005H | F4: abeyrathnasmsmb.21@uom.lk | G4: 10 | H4: 10 | I4: 10 | J4: 0.95 | K4: 10 | L4: 9 | M4: 9 | N4: 9.67 | O4: 9 | P4: 10 | Q4: 9.77 | R4: 18 | S4: 3.33 | T4: 10.38 | U4: 13.71 | V4: 51.25 | W4: 1766912722
A5: ABEYWARDANA K.D.W. | B5: 210014J | C5: 39247 | D5: 210014J | F5: abeywardanakdw.21@uom.lk | G5: 10 | H5: 8.5 | I5: 8 | J5: 0.89 | K5: 8 | L5: - | M5: 8 | N5: - | O5: 7.67 | P5: 8.72 | Q5: 8.48 | R5: 18 | S5: 4.5 | T5: 12.63 | U5: 17.13 | V5: 52.08 | W5: 1766912722
A6: ABITHAN A. | B6: 210019E | C6: 39252 | D6: 210019E | F6: abithana.21@uom.lk | G6: 10 | H6: 10 | I6: 8.5 | J6: 0.82 | K6: 10 | L6: 9 | M6: 9 | N6: 10 | O6: 8.67 | P6: 10 | Q6: 9.58 | R6: 17 | S6: 4.17 | T6: 9 | U6: 13.17 | V6: 49.33 | W6: 1766912722
A7: ADIKARAM W.K.D.N.E. | B7: 210021D | C7: 39254 | D7: 210021D | F7: adikaramwkdne.21@uom.lk | G7: - | H7: 9.5 | I7: 9 | J7: 0.92 | K7: 10 | L7: 8.5 | M7: 9 | N7: 9.67 | O7: 8.5 | P7: 10 | Q7: 9.35 | R7: 14 | S7: 3.67 | T7: 12.5 | U7: 16.17 | V7: 48.88 | W7: 1766912722
A8: ADIKARI A.A.S.D. | B8: 210022G | C8: 39255 | D8: 210022G | F8: adikariaasd.21@uom.lk | G8: 10 | H8: 10 | I8: 8.5 | J8: 0.92 | K8: 10 | L8: 9 | M8: 8.5 | N8: 9.67 | O8: 9.17 | P8: 10 | Q8: 9.63 | R8: 18 | S8: 3.17 | T8: 12.75 | U8: 15.92 | V8: 53.17 | W8: 1766912722
A9: ALAHAKOON U.M.Y.B. | B9: 210027C | C9: 39260 | D9: 210027C | F9: alahakoonumyb.21@uom.lk | G9: 10 | H9: - | I9: 10 | J9: 0.98 | K9: 10 | L9: 9 | M9: 8.67 | N9: 9.67 | O9: 8.67 | P9: 10 | Q9: 9.64 | R9: 15 | S9: 4 | T9: 10.5 | U9: 14.5 | V9: 48.77 | W9: 1766912722
A10: AMARASINGHE A.A.W.L.R. | B10: 210031H | C10: 39264 | D10: 210031H | F10: amarasingheaawlr.21@uom.lk | G10: 10 | H10: 10 | I10: 10 | J10: 0.95 | K10: 10 | L10: 8.5 | M10: 9 | N10: 9.67 | O10: 8.67 | P10: 10 | Q10: 9.77 | R10: 18 | S10: 3.33 | T10: 14.38 | U10: 17.71 | V10: 55.25 | W10: 1766912722
A11: AMARASINGHE Y.W.S.P. | B11: 210035A | C11: 39268 | D11: 210035A | E11: Electronic and Telecommunication Engineering | F11: amarasingheywsp.21@uom.lk | G11: 10 | H11: 10 | I11: 10 | J11: 0.92 | K11: 10 | L11: 10 | M11: 9 | N11: 9.67 | O11: 8.67 | P11: 10 | Q11: 9.85 | R11: 18 | S11: 2.83 | T11: 14.63 | U11: 17.46 | V11: 55.17 | W11: 1766912722
A12: AMARASURIYA G.N. | B12: 210036D | C12: 39269 | D12: 210036D | F12: amarasuriyagn.21@uom.lk | G12: 10 | H12: 10 | I12: - | J12: 1 | K12: 10 | L12: 9 | M12: 9 | N12: 9.67 | O12: 9 | P12: 10 | Q12: 9.71 | R12: 19 | S12: 4 | T12: 10.88 | U12: 14.88 | V12: 53.29 | W12: 1766912722
A13: AMARATHUNGA D.N. | B13: 210037G | C13: 39270 | D13: 210037G | F13: amarathungadn.21@uom.lk | G13: 10 | H13: 10 | I13: 8.5 | J13: 1 | K13: 10 | L13: 10 | M13: 9 | N13: 10 | O13: 10 | P13: 10 | Q13: 10 | R13: 17 | S13: 2.67 | T13: 13.5 | U13: 16.17 | V13: 53.17 | W13: 1766912722
A14: AMUGODA A.S.S. | B14: 210041M | C14: 39274 | D14: 210041M | F14: amugodaass.21@uom.lk | G14: - | H14: 10 | I14: 10 | J14: 0.98 | K14: 10 | L14: - | M14: 9 | N14: 3.67 | O14: 9.17 | P14: 10 | Q14: 8.95 | R14: 19 | S14: 3.67 | T14: 10.75 | U14: 14.42 | V14: 51.31 | W14: 1766912722
A15: BASNAYAKE B.Y.N. | B15: 210069F | C15: 39302 | D15: 210069F | F15: basnayakebyn.21@uom.lk | G15: - | H15: 10 | I15: 9 | J15: - | K15: 10 | L15: 9 | M15: 9 | N15: 10 | O15: 9.17 | P15: 10 | Q15: 9.52 | R15: 20 | S15: 4.17 | T15: 14 | U15: 18.17 | V15: 57.21 | W15: 1766912722
A16: BOTHEJU W.G.W. | B16: 210071E | C16: 39304 | D16: 210071E | F16: bothejuwgw.21@uom.lk | G16: 10 | H16: 10 | I16: - | J16: 0.89 | K16: 10 | L16: 9 | M16: 8.5 | N16: 9.67 | O16: 8.5 | P16: 10 | Q16: 9.51 | R16: 19 | S16: 2 | T16: 9.88 | U16: 11.88 | V16: 49.9 | W16: 1766912722
A17: CHANDRAJITH B.P.L. | B17: 210075U | C17: 39308 | D17: 210075U | F17: chandrajithbpl.21@uom.lk | G17: - | H17: 9.5 | I17: 9 | J17: 0.69 | K17: 9.5 | L17: 8.17 | M17: 9 | N17: 9.33 | O17: 7.83 | P17: 10 | Q17: 9.04 | R17: 18 | S17: 3.67 | T17: 12.5 | U17: 16.17 | V17: 52.25 | W17: 1766912722
A18: COORAY P.L.L.K. | B18: 210088L | C18: 39321 | D18: 210088L | F18: cooraypllk.21@uom.lk | G18: 10 | H18: 10 | I18: 10 | J18: 0.92 | K18: 10 | L18: 10 | M18: 9 | N18: 9.67 | O18: 8.67 | P18: 10 | Q18: 9.85 | R18: 18 | S18: 4.33 | T18: 11.38 | U18: 15.71 | V18: 53.42 | W18: 1766912722
A19: DABARE A.D.T. | B19: 210089P | C19: 39322 | D19: 210089P | E19: ENTC | F19: dabareadt.21@uom.lk | G19: 10 | H19: 10 | I19: 10 | J19: 1 | K19: 10 | L19: 10 | M19: 10 | N19: 10 | O19: 10 | P19: 10 | Q19: 10 | R19: 17 | S19: 2.67 | T19: 10.63 | U19: 13.29 | V19: 50.29 | W19: 1766912722
A20: DASSANAYAKE D.M.T.K.R. | B20: 210095F | C20: 39328 | D20: 210095F | F20: dassanayakedmtkr.21@uom.lk | G20: 10 | H20: 10 | I20: 8.5 | J20: 0.92 | K20: 10 | L20: 9 | M20: 9.5 | N20: 9.67 | O20: 9.17 | P20: 10 | Q20: 9.69 | R20: 17 | S20: 4.33 | T20: 9.38 | U20: 13.71 | V20: 50.08 | W20: 1766912722
A21: DE SILVA A.N.T. | B21: 210097M | C21: 39330 | D21: 210097M | F21: desilvaant.21@uom.lk | G21: 10 | H21: 10 | I21: 8.5 | J21: - | K21: 10 | L21: 9 | M21: 9 | N21: - | O21: 8.67 | P21: 10 | Q21: 9.4 | R21: 11 | S21: 3.17 | T21: 7 | U21: 10.17 | V21: 39.96 | W21: 1766912722
A22: DE ZOYSA A.K.N. | B22: 210108C | C22: 39341 | D22: 210108C | F22: dezoysaakn.21@uom.lk | G22: 10 | H22: 10 | I22: 10 | J22: 1 | K22: 10 | L22: 10 | M22: 10 | N22: 10 | O22: 10 | P22: 10 | Q22: 10 | R22: 17 | S22: 3.8 | T22: 9.25 | U22: 13.05 | V22: 50.05 | W22: 1766912722
A23: DHARMADASA W.H.M.A.D. | B23: 210121J | C23: 39354 | D23: 210121J | F23: dharmadasawhmad.21@uom.lk | G23: - | H23: - | I23: - | J23: - | K23: 10 | L23: 10 | M23: 9 | N23: 10 | O23: 8.17 | P23: - | Q23: 5.9 | R23: 12 | S23: 3.5 | T23: 8.75 | U23: 12.25 | V23: 36.04 | W23: 1766912722
A24: DILUSHANA H.M.P.S. | B24: 210130K | C24: 39363 | D24: 210130K | F24: dilushanahmps.21@uom.lk | G24: - | H24: - | I24: - | J24: - | K24: - | L24: 10 | M24: 9.5 | N24: 9.67 | O24: 8.33 | P24: 10 | Q24: 5.94 | R24: 11 | S24: 3.83 | T24: 9.13 | U24: 12.96 | V24: 35.83 | W24: 1766912722
A25: DIMAGI D.H.P. | B25: 210131N | C25: 39364 | D25: 210131N | F25: dimagidhp.21@uom.lk | G25: 10 | H25: 10 | I25: 10 | J25: 1 | K25: 10 | L25: 10 | M25: 10 | N25: 10 | O25: 10 | P25: 10 | Q25: 10 | R25: 19 | S25: 4 | T25: 12.75 | U25: 16.75 | V25: 55.75 | W25: 1766912722
A26: DISSANAYAKA D.M.P.C. | B26: 210140P | C26: 39373 | D26: 210140P | F26: dissanayakadmpc.21@uom.lk | G26: 10 | H26: 10 | I26: 9 | J26: 1 | K26: 10 | L26: 10 | M26: 9.67 | N26: 10 | O26: 10 | P26: 10 | Q26: 10 | R26: 14 | S26: 4 | T26: 12.75 | U26: 16.75 | V26: 50.75 | W26: 1766912722
A27: DISSANAYAKA D.M.S.P. | B27: 210141U | C27: 39374 | D27: 210141U | F27: dissanayakadmsp.21@uom.lk | G27: 10 | H27: 10 | I27: - | J27: 0.88 | K27: 10 | L27: 10 | M27: 9.5 | N27: 10 | O27: 9.17 | P27: 10 | Q27: 9.83 | R27: 19 | S27: 3 | T27: 10.63 | U27: 13.63 | V27: 52.29 | W27: 1766912722
A28: DISSANAYAKE D.M.S.D. | B28: 210147T | C28: 39380 | D28: 210147T | F28: dissanayakedmsd.21@uom.lk | G28: - | H28: 10 | I28: 8 | J28: 0.92 | K28: 0 | L28: 9 | M28: 9 | N28: 9.67 | O28: 8.67 | P28: 10 | Q28: 9.19 | R28: 14 | S28: 3.17 | T28: 7 | U28: 10.17 | V28: 42.54 | W28: 1766912722
A29: DODANGODA D.K.S.J. | B29: 210150V | C29: 39383 | D29: 210150V | F29: dodangodadksj.21@uom.lk | G29: 10 | H29: 10 | I29: 9 | J29: 1 | K29: 10 | L29: 10 | M29: 10 | N29: 10 | O29: 10 | P29: 10 | Q29: 10 | R29: 14 | S29: 3.8 | T29: 9.25 | U29: 13.05 | V29: 47.05 | W29: 1766912722
A30: DULNATH W.H.R. | B30: 210152E | C30: 39385 | D30: 210152E | F30: dulnathwhr.21@uom.lk | G30: 10 | H30: 10 | I30: - | J30: - | K30: 10 | L30: 9 | M30: 9.5 | N30: 10 | O30: 8.5 | P30: - | Q30: 8.38 | R30: 13 | S30: 4 | T30: 9.25 | U30: 13.25 | V30: 43 | W30: 1766912722
A31: EDIRISINGHE E.A.D.D.D. | B31: 210153H | C31: 39386 | D31: 210153H | F31: edirisingheeaddd.21@uom.lk | G31: 10 | H31: 10 | I31: 10 | J31: 0.95 | K31: 10 | L31: 10 | M31: 9 | N31: 9.67 | O31: 9 | P31: 10 | Q31: 9.9 | R31: 18 | S31: 3.67 | T31: 10.75 | U31: 14.42 | V31: 52.21 | W31: 1766912722
A32: EPA Y.L.A. | B32: 210156U | C32: 39389 | D32: 210156U | F32: epayla.21@uom.lk | G32: - | H32: 10 | I32: 10 | J32: 0.97 | K32: 10 | L32: 10 | M32: 9.5 | N32: 10 | O32: 8.67 | P32: 10 | Q32: 9.9 | R32: 18 | S32: 3.83 | T32: 12.63 | U32: 16.46 | V32: 54.25 | W32: 1766912722
A33: EPA Y.R.A. | B33: 210157A | C33: 39390 | D33: 210157A | F33: epayra.21@uom.lk | G33: - | H33: 10 | I33: 10 | J33: 0.97 | K33: 10 | L33: 10 | M33: 9.5 | N33: 10 | O33: 9.17 | P33: 10 | Q33: 9.9 | R33: 20 | S33: 3.83 | T33: 12.63 | U33: 16.46 | V33: 56.25 | W33: 1766912722
A34: FERNANDO N.I.S.P. | B34: 210162J | C34: 39395 | D34: 210162J | F34: fernandonisp.21@uom.lk | G34: - | H34: - | I34: 8.5 | J34: - | K34: 10 | L34: 9 | M34: 9.5 | N34: 9.67 | O34: 9.17 | P34: 10 | Q34: 8.23 | R34: 11 | S34: 2.17 | T34: 8.13 | U34: 10.29 | V34: 37.75 | W34: 1766912722
A35: FERNANDO W.W.R.N.S. | B35: 210169L | C35: 39402 | D35: 210169L | F35: fernandowwrns.21@uom.lk | G35: 10 | H35: 10 | I35: 10 | J35: 1 | K35: 10 | L35: 9.17 | M35: 9.5 | N35: 10 | O35: 10 | P35: 10 | Q35: 10 | R35: 17 | S35: 3.83 | T35: 10.63 | U35: 14.46 | V35: 51.46 | W35: 1766912722
A36: GALLELLA M.M.H.H.B. | B36: 210174X | C36: 39407 | D36: 210174X | F36: gallellammhhb.21@uom.lk | G36: 10 | H36: 10 | I36: 10 | J36: 0.95 | K36: 10 | L36: 10 | M36: 9 | N36: 9.67 | O36: 8.67 | P36: 10 | Q36: 9.9 | R36: 20 | S36: 4 | T36: 15 | U36: 19 | V36: 58.79 | W36: 1766912722
A37: GAMMUNE D.J.T. | B37: 210179R | C37: 39412 | D37: 210179R | F37: gammunedjt.21@uom.lk | G37: 9.33 | H37: 10 | I37: 10 | J37: - | K37: 10 | L37: 9 | M37: 9.5 | N37: 9.67 | O37: 8.5 | P37: 10 | Q37: 9.69 | R37: 14 | S37: 4.17 | T37: 14 | U37: 18.17 | V37: 51.54 | W37: 1766912722
A38: GUNAWARDANA W.N.M. | B38: 210199D | C38: 39432 | D38: 210199D | F38: gunawardanawnm.21@uom.lk | G38: 10 | H38: 10 | I38: 8.5 | J38: 0.92 | K38: 10 | L38: 9 | M38: 8.5 | N38: 10 | O38: 10 | P38: 10 | Q38: 9.77 | R38: 15 | S38: 2.83 | T38: 12 | U38: 14.83 | V38: 49.38 | W38: 1766912722
A39: GUNAWARDANE E.R.N.H. | B39: 210200C | C39: 39433 | D39: 210200C | F39: gunawardaneernh.21@uom.lk | G39: 10 | H39: 10 | I39: 9 | J39: 0.89 | K39: 10 | L39: 9 | M39: 9 | N39: 10 | O39: 10 | P39: 10 | Q39: 9.75 | R39: 19 | S39: 2.83 | T39: 12 | U39: 14.83 | V39: 53.33 | W39: 1766912722
A40: HANSINDU K.A.A. | B40: 210204R | C40: 39437 | D40: 210204R | F40: hansindukaa.21@uom.lk | G40: 10 | H40: 9.5 | I40: 8.5 | J40: 0.92 | K40: - | L40: 9 | M40: 9.5 | N40: 10 | O40: 10 | P40: 10 | Q40: 9.65 | R40: 19 | S40: 4 | T40: 13.13 | U40: 17.13 | V40: 55.42 | W40: 1766912722
...
